Workbook

Sheet Info

Sheet Process-emission_LFS
A1: Sektor | B1: Produktgruppe | C1: 2021 | D1: 2025 | E1: 2030 | F1: 2035 | G1: 2040 | H1: 2045 | I1: [%] | J1: CO2-Abscheidung [t/a] | L1: delta
A2: Nichtmetallische Mineralien | B2: Zementklinker (2.A.1) | C2: 13.6 | D2: 11.9 | E2: 12.9 | F2: 11.8 | G2: 10.8 | H2: 9.7 | I2: =H2/H$30 -> 0.485 | J2: Zement_O_Strom | K2: =SUM(Zement_O_Strom!C2:C31)/1000000 -> 8.984651 | L2: =(K2/H2)-1 -> -0.07374732
B3: Kalk (2.A.2) | C3: 4.5 | D3: 3.5 | E3: 4.2 | F3: 3.5 | G3: 3.2 | H3: 3 | I3: =H3/H$30 -> 0.15 | J3: Kalk_O_Strom | K3: =SUM(Kalk_O_Strom!C2:C53)/1000000 -> 3.4972756 | L3: =(K3/H3)-1 -> 0.16575854
B4: *Glas (2.A.3) | C4: 0.9 | D4: 0.9 | E4: 1 | F4: 1 | G4: 1 | H4: 1 | I4: =H4/H$30 -> 0.05 | J4: Summe Abscheidung [NM] | K4: =SUM(K2:K3) -> 12.481927 | L4: =(K4/H6)-1 -> -0.12099108
B5: *Keramik (2.A.4a) | C5: 0.8 | D5: 0.7 | E5: 0.8 | F5: 0.7 | G5: 0.6 | H5: 0.5 | I5: =H5/H$30 -> 0.025 | J5: MVA_O_Strom | K5: =SUM(MVA_O_Strom!C3:C56)/1000000 -> 34.60883
C6: =SUM(C2:C5) -> 19.8 | D6: =SUM(D2:D5) -> 17 | E6: =SUM(E2:E5) -> 18.9 | F6: =SUM(F2:F5) -> 17 | G6: =SUM(G2:G5) -> 15.6 | H6: =SUM(H2:H5) -> 14.2 | I6: =H6/H$30 -> 0.71 | J6: Summe Abscheidung | K6: =SUM(K5,K3,K2) -> 47.090756
A7: Chemie | B7: Ammoniak (2.B.1) | C7: 4 | D7: 3.4 | E7: 4.1 | F7: 3.8 | G7: 3.2 | H7: 0 | I7: =H7/H$30 -> 0 | J7: CO2-Bedarf [t/a]
B8: Salpetersäure (2.B.2) | C8: 0.4 | D8: 0.3 | E8: 0.2 | F8: 0.1 | G8: 0 | H8: 0 | I8: =H8/H$30 -> 0 | J8: Ammoniak_O_Strom | K8: =SUM(Ammoniak_O_Strom!C2:C5)/1000000 -> 3.722954
B9: Adipinsäure (2.B.3) | C9: 0.1 | D9: 0 | E9: 0 | F9: 0 | G9: 0 | H9: 0 | I9: =H9/H$30 -> 0 | J9: Methanol_O_Strom | K9: =SUM(Methanol_O_Strom!C2:C5)/1000000 -> 1.374032
B10: *Carbid (2.B.5) | C10: 0 | D10: 0 | E10: 0 | F10: 0 | G10: 0 | H10: 0 | I10: =H10/H$30 -> 0 | J10: Olefins_O_Strom | K10: =SUM(Olefins_O_Strom!C2:C16)/1000000 -> 13.338451
B11: *Soda ash (2.B.7) | C11: 0.5 | D11: 0.4 | E11: 0.5 | F11: 0.5 | G11: 0.4 | H11: 0.4 | I11: =H11/H$30 -> 0.02 | J11: Summ Bedarf [Chemi] | K11: =SUM(K8:K10) -> 18.435437
B12: *Petrochemie und Ruß (2.B.8) | C12: 1.4 | D12: 1.2 | E12: 1.5 | F12: 1.5 | G12: 1.4 | H12: 1.4 | I12: =H12/H$30 -> 0.07 | L12: =(K4/H30)-1 -> -0.37590367
B13: *Fluorchemikalien (2.B.9) | C13: 0.1 | D13: 0.1 | E13: 0.1 | F13: 0.1 | G13: 0.1 | H13: 0.1 | I13: =H13/H$30 -> 0.005
C14: =SUM(C7:C13) -> 6.5 | D14: =SUM(D7:D13) -> 5.4 | E14: =SUM(E7:E13) -> 6.4 | F14: =SUM(F7:F13) -> 6 | G14: =SUM(G7:G13) -> 5.1 | H14: =SUM(H7:H13) -> 1.9 | I14: =H14/H$30 -> 0.095
A15: Metalle | B15: Stahl (Teil von 2.C.1) | C15: 16.4 | D15: 17.4 | E15: 10.4 | F15: 5.8 | G15: 0 | H15: 0 | I15: =H15/H$30 -> 0
B16: *Eisenlegierungen (2.C.2) | C16: 0 | D16: 0 | E16: 0 | F16: 0 | G16: 0 | H16: 0 | I16: =H16/H$30 -> 0
B17: Aluminium (2.C.3) | C17: 0.8 | D17: 0.6 | E17: 0.8 | F17: 0.8 | G17: 0.8 | H17: 0.8 | I17: =H17/H$30 -> 0.04
B18: *Magnesium (2.C.4) | C18: 0 | D18: 0 | E18: 0 | F18: 0 | G18: 0 | H18: 0 | I18: =H18/H$30 -> 0
B19: *Blei (2.C.5) | C19: 0.1 | D19: 0.1 | E19: 0.1 | F19: 0.1 | G19: 0.1 | H19: 0.1 | I19: =H19/H$30 -> 0.005
B20: *Zink (2.C.6) | C20: 0.3 | D20: 0.3 | E20: 0.3 | F20: 0.3 | G20: 0.3 | H20: 0.3 | I20: =H20/H$30 -> 0.015
C21: =SUM(C15:C20) -> 17.6 | D21: =SUM(D15:D20) -> 18.4 | E21: =SUM(E15:E20) -> 11.6 | F21: =SUM(F15:F20) -> 7 | G21: =SUM(G15:G20) -> 1.2 | H21: =SUM(H15:H20) -> 1.2 | I21: =H21/H$30 -> 0.06
A22: Produktverwendung und Elektronik | B22: *Schmierstoffe (2.D.1) | C22: 0.2 | D22: 0.2 | E22: 0.2 | F22: 0.2 | G22: 0.2 | H22: 0.2 | I22: =H22/H$30 -> 0.01
B23: *Paraffinwachs (2.D.2) | C23: 0.5 | D23: 0.5 | E23: 0.5 | F23: 0.5 | G23: 0.5 | H23: 0.5 | I23: =H23/H$30 -> 0.025
B24: *Lösungsmittel NMVOC (2.D.3) | C24: 1.3 | D24: 1.3 | E24: 1.3 | F24: 1.3 | G24: 1.3 | H24: 1.3 | I24: =H24/H$30 -> 0.065
B25: FKWs (2.F) | C25: 8 | D25: 6.2 | E25: 3.9 | F25: 1.2 | G25: 0 | H25: 0 | I25: =H25/H$30 -> 0
B26: *Elektronik (2.E.1) | C26: 0.1 | D26: 0.1 | E26: 0.1 | F26: 0.1 | G26: 0.1 | H26: 0.1 | I26: =H26/H$30 -> 0.005
B27: *Andere Produktverwendung (2.G) | C27: 0.3 | D27: 0.3 | E27: 0.3 | F27: 0.3 | G27: 0.3 | H27: 0.3 | I27: =H27/H$30 -> 0.015
B28: *Andere (2.H) | C28: 0.1 | D28: 0.1 | E28: 0.1 | F28: 0.1 | G28: 0.1 | H28: 0.1 | I28: =H28/H$30 -> 0.005
C29: =SUM(C22:C28) -> 10.5 | D29: =SUM(D22:D28) -> 8.7 | E29: =SUM(E22:E28) -> 6.4 | F29: =SUM(F22:F28) -> 3.7 | G29: =SUM(G22:G28) -> 2.5 | H29: =SUM(H22:H28) -> 2.5 | I29: =H29/H$30 -> 0.125
A30: SUMME in MtCO2-Äq. | C30: 54.6 | D30: 49.5 | E30: 43.3 | F30: 33.7 | G30: 24.7 | H30: 20 | I30: =H30/H$30 -> 1

Sheet Abbildungen
A1: Abbildungen
A3: O45-H2 | I3: O45-H2
A4: CO2-Bedarf nach Quelle | B4: 2025 | C4: 2030 | D4: 2035 | E4: 2040 | F4: 2045 | G4: 2050 | I4: CO2-Angebot nach Quelle | J4: 2025 | K4: 2030 | L4: 2035 | M4: 2040 | N4: 2045 | O4: 2050
A5: H2-basierte Olefine | B5: 0 | C5: 0 | D5: 1.5711667 | E5: 7.8558333 | F5: 26.707885 | G5: 25.532527 | I5: Abscheidung Zement | J5: -0.30524782 | K5: -1.8479284 | L5: -4.7650261 | M5: -6.5626178 | N5: -8.4872122 | O5: -8.0360798
A6: H2-basiertes Methanol | B6: 0 | C6: 0 | D6: 0.06875 | E6: 0.6875 | F6: 1.3978264 | G6: 1.3632286 | I6: Abscheidung Kalk | J6: 0 | K6: -0.21617538 | L6: -1.1381008 | M6: -1.8243972 | N6: -3.2465368 | O6: -3.1580322
A7: Folgeprodukte Ammoniak | B7: 0 | C7: 0.07 | D7: 0.245 | E7: 0.7 | F7: 3.8174416 | G7: 3.7229542 | I7: Abscheidung MVA | J7: -0.63819825 | K7: -3.8725807 | L7: -10.517968 | M7: -16.978398 | N7: -26.697181 | O7: -27.118376
A8: Legierung Stahl | B8: 0 | C8: 0.19198667 | D8: 0.5082 | E8: 0.64936667 | F8: 0.64936667 | G8: 0.63329402
I9: Bilanz | J9: =SUM(B5:B8)+SUM(J5:J7) -> -0.94344607 | K9: =SUM(C5:C8)+SUM(K5:K7) -> -5.6746978 | L9: =SUM(D5:D8)+SUM(L5:L7) -> -14.027978 | M9: =SUM(E5:E8)+SUM(M5:M7) -> -15.472713 | N9: =SUM(F5:F8)+SUM(N5:N7) -> -5.8584102 | O9: =SUM(G5:G8)+SUM(O5:O7) -> -7.0604842
A10: T45-PtG/PtL | I10: T45-PtG/PtL
A11: CO2-Bedarf nach Quelle | B11: 2025 | C11: 2030 | D11: 2035 | E11: 2040 | F11: 2045 | G11: 2050 | I11: CO2-Angebot nach Quelle | J11: 2025 | K11: 2030 | L11: 2035 | M11: 2040 | N11: 2045 | O11: 2050
A12: H2-basierte Olefine | B12: 0 | C12: 0 | D12: 0.39279167 | E12: 6.2846667 | F12: 6.2846667 | G12: 6.2846667 | I12: Abscheidung Zement | J12: -0.34619946 | K12: -1.8535674 | L12: -5.3248471 | M12: -7.9669579 | N12: -11.249566 | O12: -10.564176
A13: H2-basiertes Methanol | B13: 0 | C13: 0 | D13: 0 | E13: 0 | F13: 0 | G13: 0 | I13: Abscheidung Kalk | J13: 0 | K13: -0.1795906 | L13: -1.1986645 | M13: -2.177599 | N13: -4.4376802 | O13: -4.5742166
A14: Folgeprodukte Ammoniak | B14: 0 | C14: 0 | D14: 0 | E14: 0 | F14: 0 | G14: 0 | I14: Abscheidung MVA | J14: -0.59349468 | K14: -3.4572417 | L14: -8.4705924 | M14: -12.548045 | N14: -17.432888 | O14: -17.432888
A15: Legierung Stahl | B15: 0 | C15: 0 | D15: 0 | E15: 0 | F15: 0 | G15: 0
I16: Bilanz | J16: =SUM(B12:B15)+SUM(J12:J14) -> -0.93969414 | K16: =SUM(C12:C15)+SUM(K12:K14) -> -5.4903997 | L16: =SUM(D12:D15)+SUM(L12:L14) -> -14.601312 | M16: =SUM(E12:E15)+SUM(M12:M14) -> -16.407935 | N16: =SUM(F12:F15)+SUM(N12:N14) -> -26.835467 | O16: =SUM(G12:G15)+SUM(O12:O14) -> -26.286613
A17: T45-RedEff | I17: T45-RedEff
A18: CO2-Bedarf nach Quelle | B18: 2025 | C18: 2030 | D18: 2035 | E18: 2040 | F18: 2045 | G18: 2050 | I18: CO2-Angebot nach Quelle | J18: 2025 | K18: 2030 | L18: 2035 | M18: 2040 | N18: 2045 | O18: 2050
A19: H2-basierte Olefine | B19: 0 | C19: 0 | D19: 0.40752135 | E19: 6.5989 | F19: 23.09615 | G19: 23.09615 | I19: Abscheidung Zement | J19: -0.3446865 | K19: -1.8400179 | L19: -5.1568056 | M19: -7.5646112 | N19: -10.180543 | O19: -9.4883231
A20: H2-basiertes Methanol | B20: 0 | C20: 0.06703125 | D20: 0.66171875 | E20: 1.30625 | F20: 1.436875 | G20: 1.436875 | I20: Abscheidung Kalk | J20: 0 | K20: -0.17842264 | L20: -1.1641993 | M20: -2.0757734 | N20: -4.0467344 | O20: -4.1404926
A21: Folgeprodukte Ammoniak | B21: 0.14175 | C21: 0.574 | D21: 1.670375 | E21: 2.793 | F21: 3.4402851 | G21: 3.3477604 | I21: Abscheidung MVA | J21: -0.59349468 | K21: -3.4572417 | L21: -8.4705924 | M21: -12.548045 | N21: -17.432888 | O21: -17.432888
A22: Legierung Stahl | B22: 0.014293125 | C22: 0.15032878 | D22: 0.30017471 | E22: 0.50080476 | F22: 0.72304279 | G22: 0.72482974
I23: Bilanz | J23: =SUM(B19:B22)+SUM(J19:J21) -> -0.78213805 | K23: =SUM(C19:C22)+SUM(K19:K21) -> -4.6843222 | L23: =SUM(D19:D22)+SUM(L19:L21) -> -11.751807 | M23: =SUM(E19:E22)+SUM(M19:M21) -> -10.989475 | N23: =SUM(F19:F22)+SUM(N19:N21) -> -2.9638124 | O23: =SUM(G19:G22)+SUM(O19:O21) -> -2.456088
A24: T45-RedGas | I24: T45-RedGas
A25: CO2-Bedarf nach Quelle | B25: 2025 | C25: 2030 | D25: 2035 | E25: 2040 | F25: 2045 | G25: 2050 | I25: CO2-Angebot nach Quelle | J25: 2025 | K25: 2030 | L25: 2035 | M25: 2040 | N25: 2045 | O25: 2050
A26: H2-basierte Olefine | B26: 0 | C26: 0 | D26: 0.39279167 | E26: 6.2846667 | F26: 21.996333 | G26: 21.996333 | I26: Abscheidung Zement | J26: -0.35238768 | K26: -1.9077915 | L26: -5.4235022 | M26: -7.9847059 | N26: -10.74536 | O26: -10.054351
A27: H2-basiertes Methanol | B27: 0 | C27: 0.06703125 | D27: 0.66171875 | E27: 1.30625 | F27: 1.436875 | G27: 1.436875 | I27: Abscheidung Kalk | J27: 0 | K27: -0.18333602 | L27: -1.2105091 | M27: -2.1669618 | N27: -4.2322801 | O27: -4.3462851
A28: Folgeprodukte Ammoniak | B28: 0.14 | C28: 0.56 | D28: 1.61 | E28: 2.66 | F28: 3.276462 | G28: 3.1883432 | I28: Abscheidung MVA | J28: -0.59349468 | K28: -3.4572417 | L28: -8.4705924 | M28: -12.548045 | N28: -17.432888 | O28: -17.432888
A29: Legierung Stahl | B29: 0.04235 | C29: 0.28233333 | D29: 0.46585 | E29: 0.5929 | F29: 0.56466667 | G29: 0.56466667
I30: Bilanz | J30: =SUM(B26:B29)+SUM(J26:J28) -> -0.76353235 | K30: =SUM(C26:C29)+SUM(K26:K28) -> -4.6390046 | L30: =SUM(D26:D29)+SUM(L26:L28) -> -11.974243 | M30: =SUM(E26:E29)+SUM(M26:M28) -> -11.855896 | N30: =SUM(F26:F29)+SUM(N26:N28) -> -5.1361909 | O30: =SUM(G26:G29)+SUM(O26:O28) -> -4.6473052
A31: O45-Strom | I31: O45-Strom
A32: CO2-Bedarf nach Quelle | B32: 2025 | C32: 2030 | D32: 2035 | E32: 2040 | F32: 2045 | G32: 2050 | I32: CO2-Angebot nach Quelle | J32: 2025 | K32: 2030 | L32: 2035 | M32: 2040 | N32: 2045 | O32: 2050
A33: H2-basierte Olefine | B33: 0 | C33: 0 | D33: 1.5711667 | E33: 7.8558333 | F33: 13.676974 | G33: 13.338451 | I33: Abscheidung Zement | J33: -0.30460092 | K33: -1.8406005 | L33: -4.9292044 | M33: -7.092695 | N33: -9.4902347 | O33: -8.9846508
A34: H2-basiertes Methanol | B34: 0 | C34: 0 | D34: 0.06875 | E34: 0.6875 | F34: 1.4089034 | G34: 1.374032 | I34: Abscheidung Kalk | J34: 0 | K34: -0.21541669 | L34: -1.1740363 | M34: -1.9603178 | N34: -3.5948839 | O34: -3.4972756
A35: Folgeprodukte Ammoniak | B35: 0 | C35: 0.07 | D35: 0.245 | E35: 0.7 | F35: 3.8174416 | G35: 3.7229542 | I35: Abscheidung MVA | J35: -0.59349468 | K35: -3.4572417 | L35: -8.4705924 | M35: -12.548045 | N35: -17.432888 | O35: -17.432888
A36: Legierung Stahl | B36: 0 | C36: 0.19198667 | D36: 0.46585 | E36: 0.56466667 | F36: 0.56466667 | G36: 0.55069046 | I36: Abscheidung Chem.Rec. | J36: 0
I37: Bilanz | J37: =SUM(B33:B36)+SUM(J33:J35) -> -0.8980956 | K37: =SUM(C33:C36)+SUM(K33:K35) -> -5.2512722 | L37: =SUM(D33:D36)+SUM(L33:L35) -> -12.223066 | M37: =SUM(E33:E36)+SUM(M33:M35) -> -11.793058 | N37: =SUM(F33:F36)+SUM(N33:N35) -> -11.05002 | O37: =SUM(G33:G36)+SUM(O33:O35) -> -10.928686

Sheet Assumptions
A2: Year 2045 is equal to 2050 and 2021 is assumped to be 2020
A3: using fixed share scaling based on the 2045 regional share
A4: For consistency the total are based on LFS even in 2045

Sheet Process-emissions
A1: Scenario | B1: Country | C1: Energy_carrier | D1: Sector | E1: Region | F1: Name_Region | G1: Subsector | H1: Application | I1: Technologie | J1: latitude | K1: longitude | L1: Unit | M1: 2020 | N1: 2025 | O1: 2030 | P1: 2035 | Q1: 2040 | R1: 2045 | S1: 2050
A2: Orientierungsszenario_Strom | B2: DE | C2: process_emissions | D2: Industry | E2: DE11C | F2: Heidenheim | G2: Cement clinker | H2: CO2 capture | J2: 48.653687 | K2: 10.162468 | L2: CO2-Abscheidung [Mt/a] | M2: 0.41305296 | N2: 0.36142134 | O2: 0.39179288 | P2: 0.35838419 | Q2: 0.32801265 | R2: 0.29460395 | S2: 0.29460395
A3: Orientierungsszenario_Strom | B3: DE | C3: process_emissions | D3: Industry | E3: DE128 | F3: Rhein-Neckar-Kreis | G3: Cement clinker | H3: CO2 capture | J3: 49.357679 | K3: 8.6858324 | L3: CO2-Abscheidung [Mt/a] | M3: 0.38308692 | N3: 0.38308692 | O3: 0.33520105 | P3: 0.36336921 | Q3: 0.33238424 | R3: 0.30421608 | S3: 0.30421608
A4: Orientierungsszenario_Strom | B4: DE | C4: process_emissions | D4: Industry | E4: DE123 | F4: Karlsruhe, Landkreis | G4: Cement clinker | H4: CO2 capture | J4: 49.018413 | K4: 8.6124897 | L4: CO2-Abscheidung [Mt/a] | M4: 0.35976088 | N4: 0.35976088 | O4: 0.31479077 | P4: 0.34124378 | Q4: 0.31214547 | R4: 0.28569246 | S4: 0.28569246
A5: Orientierungsszenario_Strom | B5: DE | C5: process_emissions | D5: Industry | E5: DE145 | F5: Alb-Donau-Kreis | G5: Cement clinker | H5: CO2 capture | J5: 48.331986 | K5: 9.7304687 | L5: CO2-Abscheidung [Mt/a] | M5: 0.45278304 | N5: 0.45278304 | O5: 0.39618516 | P5: 0.42947803 | Q5: 0.39285587 | R5: 0.359563 | S5: 0.359563
A6: Orientierungsszenario_Strom | B6: DE | C6: process_emissions | D6: Industry | E6: DE145 | F6: Alb-Donau-Kreis | G6: Cement clinker | H6: CO2 capture | J6: 48.368603 | K6: 9.7346784 | L6: CO2-Abscheidung [Mt/a] | M6: 0.60784704 | N6: 0.60784704 | O6: 0.53186616 | P6: 0.57656079 | Q6: 0.52739669 | R6: 0.48270206 | S6: 0.48270206
A7: Orientierungsszenario_Strom | B7: DE | C7: process_emissions | D7: Industry | E7: DE143 | F7: Zollernalbkreis | G7: Cement clinker | H7: CO2 capture | J7: 48.227041 | K7: 8.7790961 | L7: CO2-Abscheidung [Mt/a] | M7: 0.5262956 | N7: 0.5262956 | O7: 0.46050865 | P7: 0.49920685 | Q7: 0.45663883 | R7: 0.41794062 | S7: 0.41794062
A8: Orientierungsszenario_Strom | B8: DE | C8: process_emissions | D8: Industry | E8: DEF0E | F8: Steinburg | G8: Cement clinker | H8: CO2 capture | J8: 53.874165 | K8: 9.5832686 | L8: CO2-Abscheidung [Mt/a] | M8: 0.79108328 | N8: 0.79108328 | O8: 0.69219787 | P8: 0.75036576 | Q8: 0.68638108 | R8: 0.6282132 | S8: 0.6282132
A9: Orientierungsszenario_Strom | B9: DE | C9: process_emissions | D9: Industry | E9: DE929 | F9: Region Hannover | G9: Cement clinker | H9: CO2 capture | J9: 52.349831 | K9: 9.8859339 | L9: CO2-Abscheidung [Mt/a] | M9: 0.46625868 | N9: 0.46625868 | O9: 0.40797635 | P9: 0.44226007 | Q9: 0.40454797 | R9: 0.37026425 | S9: 0.37026425
A10: Orientierungsszenario_Strom | B10: DE | C10: process_emissions | D10: Industry | E10: DEA38 | F10: Warendorf | G10: Cement clinker | H10: CO2 capture | J10: 51.765174 | K10: 8.0540288 | L10: CO2-Abscheidung [Mt/a] | M10: 0.41116984 | N10: 0.41116984 | O10: 0.35977361 | P10: 0.39000669 | Q10: 0.3567503 | R10: 0.32651723 | S10: 0.32651723
A11: Orientierungsszenario_Strom | B11: DE | C11: process_emissions | D11: Industry | E11: DEA37 | F11: Steinfurt | G11: Cement clinker | H11: CO2 capture | J11: 52.174986 | K11: 7.8878276 | L11: CO2-Abscheidung [Mt/a] | M11: 0.78009608 | N11: 0.78009608 | O11: 0.68258407 | P11: 0.73994407 | Q11: 0.67684807 | R11: 0.61948806 | S11: 0.61948806
A12: Orientierungsszenario_Strom | B12: DE | C12: process_emissions | D12: Industry | E12: DEA47 | F12: Paderborn | G12: Cement clinker | H12: CO2 capture | J12: 51.698988 | K12: 8.7470409 | L12: CO2-Abscheidung [Mt/a] | M12: 0.16345647 | N12: 0.16345647 | O12: 0.14302441 | P12: 0.15504327 | Q12: 0.14182253 | R12: 0.12980367 | S12: 0.12980367
A13: Orientierungsszenario_Strom | B13: DE | C13: process_emissions | D13: Industry | E13: DEA5B | F13: Soest | G13: Cement clinker | H13: CO2 capture | J13: 51.622561 | K13: 8.5043929 | L13: CO2-Abscheidung [Mt/a] | M13: 0.18801528 | N13: 0.18801528 | O13: 0.16451337 | P13: 0.17833803 | Q13: 0.16313091 | R13: 0.14930625 | S13: 0.14930625
... A387: Industrie-CCS | B387: DE | C387: process_emissions | D387: Industry | E387: DEF05 | F387: Dithmarschen | G387: Refinery | H387: CO2 capture | J387: 53.983279 | K387: 9.098461 | L387: CO2-Abscheidung [Mt/a] | M387: 0 | N387: 0 | O387: 0 | P387: 0.628667 | Q387: 1.257333 | R387: 1.886 | S387: 1.886

Sheet Pivot_compare
A1: Region | B1: (Alle)
A3: Zeilenbeschriftungen | B3: Summe von 2025 | C3: Summe von 2030 | D3: Summe von 2035 | E3: Summe von 2040 | F3: Summe von 2045 | G3: Summe von 2050
A4: Industrie-CCS | B4: 17.641863 | C4: 19.587613 | D4: 44.619686 | E4: 67.082671 | F4: 90.546979 | G4: 90.546979
A5: Cement clinker | B5: 13.548368 | C5: 11.930372 | D5: 12.866591 | E5: 11.769628 | F5: 10.766591 | G5: 10.766591
A6: Chemical park | B6: 0 | C6: 0 | D6: 4.524001 | E6: 9.047999 | F6: 13.572 | G6: 13.572
A7: Iron and steel | B7: 0 | C7: 0 | D7: 8.426167 | E7: 16.852333 | F7: 25.2785 | G7: 25.2785
A8: Lime | B8: 3.5 | C8: 4.2 | D8: 3.5 | E8: 3.2 | F8: 3 | G8: 3
A9: municipal waste incinerator. | B9: 0.59349467 | C9: 3.4572417 | D9: 8.4705924 | E9: 12.548045 | F9: 17.432888 | G9: 17.432888
A10: Refinery | B10: 0 | C10: 0 | D10: 5.598667 | E10: 11.197333 | F10: 16.796 | G10: 16.796
A11: Steam cracker | B11: 0 | C11: 0 | D11: 1.233667 | E11: 2.467333 | F11: 3.701 | G11: 3.701
A12: Orientierungsszenario_Strom | B12: 17.641863 | C12: 19.587613 | D12: 24.837184 | E12: 27.517673 | F12: 31.199479 | G12: 31.199479
A13: Cement clinker | B13: 13.548368 | C13: 11.930372 | D13: 12.866591 | E13: 11.769628 | F13: 10.766591 | G13: 10.766591
A14: Lime | B14: 3.5 | C14: 4.2 | D14: 3.5 | E14: 3.2 | F14: 3 | G14: 3
A15: municipal waste incinerator. | B15: 0.59349467 | C15: 3.4572417 | D15: 8.4705924 | E15: 12.548045 | F15: 17.432888 | G15: 17.432888
A16: (Leer)
A17: (Leer)
A18: Gesamtergebnis | B18: 35.283726 | C18: 39.175226 | D18: 69.456869 | E18: 94.600344 | F18: 121.74646 | G18: 121.74646
A23: year | B23: Scenario | C23: Cement clinker | D23: Chemical park | E23: Iron and steel | F23: Lime | G23: municipal waste incinerator. | H23: Refinery | I23: Steam cracker
A24: 2020 | B24: Industrie-CCS | C24: {=IF(LOOKUP(2,1/($A$24:$A24<>""),$A$24:$A24)<2025,0,IFERROR(GETPIVOTDATA("Summe von "&LOOKUP(2,1/($A$24:$A24<>""),$A$24:$A24),$A$3,"Scenario",$B24,"Subsector",C$23),0))} -> 0 | D24: {=IF(LOOKUP(2,1/($A$24:$A24<>""),$A$24:$A24)<2025,0,IFERROR(GETPIVOTDATA("Summe von "&LOOKUP(2,1/($A$24:$A24<>""),$A$24:$A24),$A$3,"Scenario",$B24,"Subsector",D$23),0))} -> 0 | E24: {=IF(LOOKUP(2,1/($A$24:$A24<>""),$A$24:$A24)<2025,0,IFERROR(GETPIVOTDATA("Summe von "&LOOKUP(2,1/($A$24:$A24<>""),$A$24:$A24),$A$3,"Scenario",$B24,"Subsector",E$23),0))} -> 0 | F24: {=IF(LOOKUP(2,1/($A$24:$A24<>""),$A$24:$A24)<2025,0,IFERROR(GETPIVOTDATA("Summe von "&LOOKUP(2,1/($A$24:$A24<>""),$A$24:$A24),$A$3,"Scenario",$B24,"Subsector",F$23),0))} -> 0 | G24: {=IF(LOOKUP(2,1/($A$24:$A24<>""),$A$24:$A24)<2025,0,IFERROR(GETPIVOTDATA("Summe von "&LOOKUP(2,1/($A$24:$A24<>""),$A$24:$A24),$A$3,"Scenario",$B24,"Subsector",G$23),0))} -> 0 | H24: {=IF(LOOKUP(2,1/($A$24:$A24<>""),$A$24:$A24)<2025,0,IFERROR(GETPIVOTDATA("Summe von "&LOOKUP(2,1/($A$24:$A24<>""),$A$24:$A24),$A$3,"Scenario",$B24,"Subsector",H$23),0))} -> 0 | I24: {=IF(LOOKUP(2,1/($A$24:$A24<>""),$A$24:$A24)<2025,0,IFERROR(GETPIVOTDATA("Summe von "&LOOKUP(2,1/($A$24:$A24<>""),$A$24:$A24),$A$3,"Scenario",$B24,"Subsector",I$23),0))} -> 0
B25: Orientierungsszenario_Strom | C25: {=IF(LOOKUP(2,1/($A$24:$A25<>""),$A$24:$A25)<2025,0,IFERROR(GETPIVOTDATA("Summe von "&LOOKUP(2,1/($A$24:$A25<>""),$A$24:$A25),$A$3,"Scenario",$B25,"Subsector",C$23),0))} -> 0 | D25: {=IF(LOOKUP(2,1/($A$24:$A25<>""),$A$24:$A25)<2025,0,IFERROR(GETPIVOTDATA("Summe von "&LOOKUP(2,1/($A$24:$A25<>""),$A$24:$A25),$A$3,"Scenario",$B25,"Subsector",D$23),0))} -> 0 | E25: {=IF(LOOKUP(2,1/($A$24:$A25<>""),$A$24:$A25)<2025,0,IFERROR(GETPIVOTDATA("Summe von "&LOOKUP(2,1/($A$24:$A25<>""),$A$24:$A25),$A$3,"Scenario",$B25,"Subsector",E$23),0))} -> 0 | F25: {=IF(LOOKUP(2,1/($A$24:$A25<>""),$A$24:$A25)<2025,0,IFERROR(GETPIVOTDATA("Summe von "&LOOKUP(2,1/($A$24:$A25<>""),$A$24:$A25),$A$3,"Scenario",$B25,"Subsector",F$23),0))} -> 0 | G25: {=IF(LOOKUP(2,1/($A$24:$A25<>""),$A$24:$A25)<2025,0,IFERROR(GETPIVOTDATA("Summe von "&LOOKUP(2,1/($A$24:$A25<>""),$A$24:$A25),$A$3,"Scenario",$B25,"Subsector",G$23),0))} -> 0 | H25: {=IF(LOOKUP(2,1/($A$24:$A25<>""),$A$24:$A25)<2025,0,IFERROR(GETPIVOTDATA("Summe von "&LOOKUP(2,1/($A$24:$A25<>""),$A$24:$A25),$A$3,"Scenario",$B25,"Subsector",H$23),0))} -> 0 | I25: {=IF(LOOKUP(2,1/($A$24:$A25<>""),$A$24:$A25)<2025,0,IFERROR(GETPIVOTDATA("Summe von "&LOOKUP(2,1/($A$24:$A25<>""),$A$24:$A25),$A$3,"Scenario",$B25,"Subsector",I$23),0))} -> 0
A26: 2025 | B26: Industrie-CCS | C26: {=IF(LOOKUP(2,1/($A$24:$A26<>""),$A$24:$A26)<2025,0,IFERROR(GETPIVOTDATA("Summe von "&LOOKUP(2,1/($A$24:$A26<>""),$A$24:$A26),$A$3,"Scenario",$B26,"Subsector",C$23),0))} -> 13.548368 | D26: {=IF(LOOKUP(2,1/($A$24:$A26<>""),$A$24:$A26)<2025,0,IFERROR(GETPIVOTDATA("Summe von "&LOOKUP(2,1/($A$24:$A26<>""),$A$24:$A26),$A$3,"Scenario",$B26,"Subsector",D$23),0))} -> 0 | E26: {=IF(LOOKUP(2,1/($A$24:$A26<>""),$A$24:$A26)<2025,0,IFERROR(GETPIVOTDATA("Summe von "&LOOKUP(2,1/($A$24:$A26<>""),$A$24:$A26),$A$3,"Scenario",$B26,"Subsector",E$23),0))} -> 0 | F26: {=IF(LOOKUP(2,1/($A$24:$A26<>""),$A$24:$A26)<2025,0,IFERROR(GETPIVOTDATA("Summe von "&LOOKUP(2,1/($A$24:$A26<>""),$A$24:$A26),$A$3,"Scenario",$B26,"Subsector",F$23),0))} -> 3.5 | G26: {=IF(LOOKUP(2,1/($A$24:$A26<>""),$A$24:$A26)<2025,0,IFERROR(GETPIVOTDATA("Summe von "&LOOKUP(2,1/($A$24:$A26<>""),$A$24:$A26),$A$3,"Scenario",$B26,"Subsector",G$23),0))} -> 0.59349467 | H26: {=IF(LOOKUP(2,1/($A$24:$A26<>""),$A$24:$A26)<2025,0,IFERROR(GETPIVOTDATA("Summe von "&LOOKUP(2,1/($A$24:$A26<>""),$A$24:$A26),$A$3,"Scenario",$B26,"Subsector",H$23),0))} -> 0 | I26: {=IF(LOOKUP(2,1/($A$24:$A26<>""),$A$24:$A26)<2025,0,IFERROR(GETPIVOTDATA("Summe von "&LOOKUP(2,1/($A$24:$A26<>""),$A$24:$A26),$A$3,"Scenario",$B26,"Subsector",I$23),0))} -> 0
B27: Orientierungsszenario_Strom | C27: {=IF(LOOKUP(2,1/($A$24:$A27<>""),$A$24:$A27)<2025,0,IFERROR(GETPIVOTDATA("Summe von "&LOOKUP(2,1/($A$24:$A27<>""),$A$24:$A27),$A$3,"Scenario",$B27,"Subsector",C$23),0))} -> 13.548368 | D27: {=IF(LOOKUP(2,1/($A$24:$A27<>""),$A$24:$A27)<2025,0,IFERROR(GETPIVOTDATA("Summe von "&LOOKUP(2,1/($A$24:$A27<>""),$A$24:$A27),$A$3,"Scenario",$B27,"Subsector",D$23),0))} -> 0 | E27: {=IF(LOOKUP(2,1/($A$24:$A27<>""),$A$24:$A27)<2025,0,IFERROR(GETPIVOTDATA("Summe von "&LOOKUP(2,1/($A$24:$A27<>""),$A$24:$A27),$A$3,"Scenario",$B27,"Subsector",E$23),0))} -> 0 | F27: {=IF(LOOKUP(2,1/($A$24:$A27<>""),$A$24:$A27)<2025,0,IFERROR(GETPIVOTDATA("Summe von "&LOOKUP(2,1/($A$24:$A27<>""),$A$24:$A27),$A$3,"Scenario",$B27,"Subsector",F$23),0))} -> 3.5 | G27: {=IF(LOOKUP(2,1/($A$24:$A27<>""),$A$24:$A27)<2025,0,IFERROR(GETPIVOTDATA("Summe von "&LOOKUP(2,1/($A$24:$A27<>""),$A$24:$A27),$A$3,"Scenario",$B27,"Subsector",G$23),0))} -> 0.59349467 | H27: {=IF(LOOKUP(2,1/($A$24:$A27<>""),$A$24:$A27)<2025,0,IFERROR(GETPIVOTDATA("Summe von "&LOOKUP(2,1/($A$24:$A27<>""),$A$24:$A27),$A$3,"Scenario",$B27,"Subsector",H$23),0))} -> 0 | I27: {=IF(LOOKUP(2,1/($A$24:$A27<>""),$A$24:$A27)<2025,0,IFERROR(GETPIVOTDATA("Summe von "&LOOKUP(2,1/($A$24:$A27<>""),$A$24:$A27),$A$3,"Scenario",$B27,"Subsector",I$23),0))} -> 0
A28: 2030 | B28: Industrie-CCS | C28: {=IF(LOOKUP(2,1/($A$24:$A28<>""),$A$24:$A28)<2025,0,IFERROR(GETPIVOTDATA("Summe von "&LOOKUP(2,1/($A$24:$A28<>""),$A$24:$A28),$A$3,"Scenario",$B28,"Subsector",C$23),0))} -> 11.930372 | D28: {=IF(LOOKUP(2,1/($A$24:$A28<>""),$A$24:$A28)<2025,0,IFERROR(GETPIVOTDATA("Summe von "&LOOKUP(2,1/($A$24:$A28<>""),$A$24:$A28),$A$3,"Scenario",$B28,"Subsector",D$23),0))} -> 0 | E28: {=IF(LOOKUP(2,1/($A$24:$A28<>""),$A$24:$A28)<2025,0,IFERROR(GETPIVOTDATA("Summe von "&LOOKUP(2,1/($A$24:$A28<>""),$A$24:$A28),$A$3,"Scenario",$B28,"Subsector",E$23),0))} -> 0 | F28: {=IF(LOOKUP(2,1/($A$24:$A28<>""),$A$24:$A28)<2025,0,IFERROR(GETPIVOTDATA("Summe von "&LOOKUP(2,1/($A$24:$A28<>""),$A$24:$A28),$A$3,"Scenario",$B28,"Subsector",F$23),0))} -> 4.2 | G28: {=IF(LOOKUP(2,1/($A$24:$A28<>""),$A$24:$A28)<2025,0,IFERROR(GETPIVOTDATA("Summe von "&LOOKUP(2,1/($A$24:$A28<>""),$A$24:$A28),$A$3,"Scenario",$B28,"Subsector",G$23),0))} -> 3.4572417 | H28: {=IF(LOOKUP(2,1/($A$24:$A28<>""),$A$24:$A28)<2025,0,IFERROR(GETPIVOTDATA("Summe von "&LOOKUP(2,1/($A$24:$A28<>""),$A$24:$A28),$A$3,"Scenario",$B28,"Subsector",H$23),0))} -> 0 | I28: {=IF(LOOKUP(2,1/($A$24:$A28<>""),$A$24:$A28)<2025,0,IFERROR(GETPIVOTDATA("Summe von "&LOOKUP(2,1/($A$24:$A28<>""),$A$24:$A28),$A$3,"Scenario",$B28,"Subsector",I$23),0))} -> 0
B29: Orientierungsszenario_Strom | C29: {=IF(LOOKUP(2,1/($A$24:$A29<>""),$A$24:$A29)<2025,0,IFERROR(GETPIVOTDATA("Summe von "&LOOKUP(2,1/($A$24:$A29<>""),$A$24:$A29),$A$3,"Scenario",$B29,"Subsector",C$23),0))} -> 11.930372 | D29: {=IF(LOOKUP(2,1/($A$24:$A29<>""),$A$24:$A29)<2025,0,IFERROR(GETPIVOTDATA("Summe von "&LOOKUP(2,1/($A$24:$A29<>""),$A$24:$A29),$A$3,"Scenario",$B29,"Subsector",D$23),0))} -> 0 | E29: {=IF(LOOKUP(2,1/($A$24:$A29<>""),$A$24:$A29)<2025,0,IFERROR(GETPIVOTDATA("Summe von "&LOOKUP(2,1/($A$24:$A29<>""),$A$24:$A29),$A$3,"Scenario",$B29,"Subsector",E$23),0))} -> 0 | F29: {=IF(LOOKUP(2,1/($A$24:$A29<>""),$A$24:$A29)<2025,0,IFERROR(GETPIVOTDATA("Summe von "&LOOKUP(2,1/($A$24:$A29<>""),$A$24:$A29),$A$3,"Scenario",$B29,"Subsector",F$23),0))} -> 4.2 | G29: {=IF(LOOKUP(2,1/($A$24:$A29<>""),$A$24:$A29)<2025,0,IFERROR(GETPIVOTDATA("Summe von "&LOOKUP(2,1/($A$24:$A29<>""),$A$24:$A29),$A$3,"Scenario",$B29,"Subsector",G$23),0))} -> 3.4572417 | H29: {=IF(LOOKUP(2,1/($A$24:$A29<>""),$A$24:$A29)<2025,0,IFERROR(GETPIVOTDATA("Summe von "&LOOKUP(2,1/($A$24:$A29<>""),$A$24:$A29),$A$3,"Scenario",$B29,"Subsector",H$23),0))} -> 0 | I29: {=IF(LOOKUP(2,1/($A$24:$A29<>""),$A$24:$A29)<2025,0,IFERROR(GETPIVOTDATA("Summe von "&LOOKUP(2,1/($A$24:$A29<>""),$A$24:$A29),$A$3,"Scenario",$B29,"Subsector",I$23),0))} -> 0
A30: 2035 | B30: Industrie-CCS | C30: {=IF(LOOKUP(2,1/($A$24:$A30<>""),$A$24:$A30)<2025,0,IFERROR(GETPIVOTDATA("Summe von "&LOOKUP(2,1/($A$24:$A30<>""),$A$24:$A30),$A$3,"Scenario",$B30,"Subsector",C$23),0))} -> 12.866591 | D30: {=IF(LOOKUP(2,1/($A$24:$A30<>""),$A$24:$A30)<2025,0,IFERROR(GETPIVOTDATA("Summe von "&LOOKUP(2,1/($A$24:$A30<>""),$A$24:$A30),$A$3,"Scenario",$B30,"Subsector",D$23),0))} -> 4.524001 | E30: {=IF(LOOKUP(2,1/($A$24:$A30<>""),$A$24:$A30)<2025,0,IFERROR(GETPIVOTDATA("Summe von "&LOOKUP(2,1/($A$24:$A30<>""),$A$24:$A30),$A$3,"Scenario",$B30,"Subsector",E$23),0))} -> 8.426167 | F30: {=IF(LOOKUP(2,1/($A$24:$A30<>""),$A$24:$A30)<2025,0,IFERROR(GETPIVOTDATA("Summe von "&LOOKUP(2,1/($A$24:$A30<>""),$A$24:$A30),$A$3,"Scenario",$B30,"Subsector",F$23),0))} -> 3.5 | G30: {=IF(LOOKUP(2,1/($A$24:$A30<>""),$A$24:$A30)<2025,0,IFERROR(GETPIVOTDATA("Summe von "&LOOKUP(2,1/($A$24:$A30<>""),$A$24:$A30),$A$3,"Scenario",$B30,"Subsector",G$23),0))} -> 8.4705924 | H30: {=IF(LOOKUP(2,1/($A$24:$A30<>""),$A$24:$A30)<2025,0,IFERROR(GETPIVOTDATA("Summe von "&LOOKUP(2,1/($A$24:$A30<>""),$A$24:$A30),$A$3,"Scenario",$B30,"Subsector",H$23),0))} -> 5.598667 | I30: {=IF(LOOKUP(2,1/($A$24:$A30<>""),$A$24:$A30)<2025,0,IFERROR(GETPIVOTDATA("Summe von "&LOOKUP(2,1/($A$24:$A30<>""),$A$24:$A30),$A$3,"Scenario",$B30,"Subsector",I$23),0))} -> 1.233667
B31: Orientierungsszenario_Strom | C31: {=IF(LOOKUP(2,1/($A$24:$A31<>""),$A$24:$A31)<2025,0,IFERROR(GETPIVOTDATA("Summe von "&LOOKUP(2,1/($A$24:$A31<>""),$A$24:$A31),$A$3,"Scenario",$B31,"Subsector",C$23),0))} -> 12.866591 | D31: {=IF(LOOKUP(2,1/($A$24:$A31<>""),$A$24:$A31)<2025,0,IFERROR(GETPIVOTDATA("Summe von "&LOOKUP(2,1/($A$24:$A31<>""),$A$24:$A31),$A$3,"Scenario",$B31,"Subsector",D$23),0))} -> 0 | E31: {=IF(LOOKUP(2,1/($A$24:$A31<>""),$A$24:$A31)<2025,0,IFERROR(GETPIVOTDATA("Summe von "&LOOKUP(2,1/($A$24:$A31<>""),$A$24:$A31),$A$3,"Scenario",$B31,"Subsector",E$23),0))} -> 0 | F31: {=IF(LOOKUP(2,1/($A$24:$A31<>""),$A$24:$A31)<2025,0,IFERROR(GETPIVOTDATA("Summe von "&LOOKUP(2,1/($A$24:$A31<>""),$A$24:$A31),$A$3,"Scenario",$B31,"Subsector",F$23),0))} -> 3.5 | G31: {=IF(LOOKUP(2,1/($A$24:$A31<>""),$A$24:$A31)<2025,0,IFERROR(GETPIVOTDATA("Summe von "&LOOKUP(2,1/($A$24:$A31<>""),$A$24:$A31),$A$3,"Scenario",$B31,"Subsector",G$23),0))} -> 8.4705924 | H31: {=IF(LOOKUP(2,1/($A$24:$A31<>""),$A$24:$A31)<2025,0,IFERROR(GETPIVOTDATA("Summe von "&LOOKUP(2,1/($A$24:$A31<>""),$A$24:$A31),$A$3,"Scenario",$B31,"Subsector",H$23),0))} -> 0 | I31: {=IF(LOOKUP(2,1/($A$24:$A31<>""),$A$24:$A31)<2025,0,IFERROR(GETPIVOTDATA("Summe von "&LOOKUP(2,1/($A$24:$A31<>""),$A$24:$A31),$A$3,"Scenario",$B31,"Subsector",I$23),0))} -> 0
A32: 2040 | B32: Industrie-CCS | C32: {=IF(LOOKUP(2,1/($A$24:$A32<>""),$A$24:$A32)<2025,0,IFERROR(GETPIVOTDATA("Summe von "&LOOKUP(2,1/($A$24:$A32<>""),$A$24:$A32),$A$3,"Scenario",$B32,"Subsector",C$23),0))} -> 11.769628 | D32: {=IF(LOOKUP(2,1/($A$24:$A32<>""),$A$24:$A32)<2025,0,IFERROR(GETPIVOTDATA("Summe von "&LOOKUP(2,1/($A$24:$A32<>""),$A$24:$A32),$A$3,"Scenario",$B32,"Subsector",D$23),0))} -> 9.047999 | E32: {=IF(LOOKUP(2,1/($A$24:$A32<>""),$A$24:$A32)<2025,0,IFERROR(GETPIVOTDATA("Summe von "&LOOKUP(2,1/($A$24:$A32<>""),$A$24:$A32),$A$3,"Scenario",$B32,"Subsector",E$23),0))} -> 16.852333 | F32: {=IF(LOOKUP(2,1/($A$24:$A32<>""),$A$24:$A32)<2025,0,IFERROR(GETPIVOTDATA("Summe von "&LOOKUP(2,1/($A$24:$A32<>""),$A$24:$A32),$A$3,"Scenario",$B32,"Subsector",F$23),0))} -> 3.2 | G32: {=IF(LOOKUP(2,1/($A$24:$A32<>""),$A$24:$A32)<2025,0,IFERROR(GETPIVOTDATA("Summe von "&LOOKUP(2,1/($A$24:$A32<>""),$A$24:$A32),$A$3,"Scenario",$B32,"Subsector",G$23),0))} -> 12.548045 | H32: {=IF(LOOKUP(2,1/($A$24:$A32<>""),$A$24:$A32)<2025,0,IFERROR(GETPIVOTDATA("Summe von "&LOOKUP(2,1/($A$24:$A32<>""),$A$24:$A32),$A$3,"Scenario",$B32,"Subsector",H$23),0))} -> 11.197333 | I32: {=IF(LOOKUP(2,1/($A$24:$A32<>""),$A$24:$A32)<2025,0,IFERROR(GETPIVOTDATA("Summe von "&LOOKUP(2,1/($A$24:$A32<>""),$A$24:$A32),$A$3,"Scenario",$B32,"Subsector",I$23),0))} -> 2.467333
B33: Orientierungsszenario_Strom | C33: {=IF(LOOKUP(2,1/($A$24:$A33<>""),$A$24:$A33)<2025,0,IFERROR(GETPIVOTDATA("Summe von "&LOOKUP(2,1/($A$24:$A33<>""),$A$24:$A33),$A$3,"Scenario",$B33,"Subsector",C$23),0))} -> 11.769628 | D33: {=IF(LOOKUP(2,1/($A$24:$A33<>""),$A$24:$A33)<2025,0,IFERROR(GETPIVOTDATA("Summe von "&LOOKUP(2,1/($A$24:$A33<>""),$A$24:$A33),$A$3,"Scenario",$B33,"Subsector",D$23),0))} -> 0 | E33: {=IF(LOOKUP(2,1/($A$24:$A33<>""),$A$24:$A33)<2025,0,IFERROR(GETPIVOTDATA("Summe von "&LOOKUP(2,1/($A$24:$A33<>""),$A$24:$A33),$A$3,"Scenario",$B33,"Subsector",E$23),0))} -> 0 | F33: {=IF(LOOKUP(2,1/($A$24:$A33<>""),$A$24:$A33)<2025,0,IFERROR(GETPIVOTDATA("Summe von "&LOOKUP(2,1/($A$24:$A33<>""),$A$24:$A33),$A$3,"Scenario",$B33,"Subsector",F$23),0))} -> 3.2 | G33: {=IF(LOOKUP(2,1/($A$24:$A33<>""),$A$24:$A33)<2025,0,IFERROR(GETPIVOTDATA("Summe von "&LOOKUP(2,1/($A$24:$A33<>""),$A$24:$A33),$A$3,"Scenario",$B33,"Subsector",G$23),0))} -> 12.548045 | H33: {=IF(LOOKUP(2,1/($A$24:$A33<>""),$A$24:$A33)<2025,0,IFERROR(GETPIVOTDATA("Summe von "&LOOKUP(2,1/($A$24:$A33<>""),$A$24:$A33),$A$3,"Scenario",$B33,"Subsector",H$23),0))} -> 0 | I33: {=IF(LOOKUP(2,1/($A$24:$A33<>""),$A$24:$A33)<2025,0,IFERROR(GETPIVOTDATA("Summe von "&LOOKUP(2,1/($A$24:$A33<>""),$A$24:$A33),$A$3,"Scenario",$B33,"Subsector",I$23),0))} -> 0
A34: 2045 | B34: Industrie-CCS | C34: {=IF(LOOKUP(2,1/($A$24:$A34<>""),$A$24:$A34)<2025,0,IFERROR(GETPIVOTDATA("Summe von "&LOOKUP(2,1/($A$24:$A34<>""),$A$24:$A34),$A$3,"Scenario",$B34,"Subsector",C$23),0))} -> 10.766591 | D34: {=IF(LOOKUP(2,1/($A$24:$A34<>""),$A$24:$A34)<2025,0,IFERROR(GETPIVOTDATA("Summe von "&LOOKUP(2,1/($A$24:$A34<>""),$A$24:$A34),$A$3,"Scenario",$B34,"Subsector",D$23),0))} -> 13.572 | E34: {=IF(LOOKUP(2,1/($A$24:$A34<>""),$A$24:$A34)<2025,0,IFERROR(GETPIVOTDATA("Summe von "&LOOKUP(2,1/($A$24:$A34<>""),$A$24:$A34),$A$3,"Scenario",$B34,"Subsector",E$23),0))} -> 25.2785 | F34: {=IF(LOOKUP(2,1/($A$24:$A34<>""),$A$24:$A34)<2025,0,IFERROR(GETPIVOTDATA("Summe von "&LOOKUP(2,1/($A$24:$A34<>""),$A$24:$A34),$A$3,"Scenario",$B34,"Subsector",F$23),0))} -> 3 | G34: {=IF(LOOKUP(2,1/($A$24:$A34<>""),$A$24:$A34)<2025,0,IFERROR(GETPIVOTDATA("Summe von "&LOOKUP(2,1/($A$24:$A34<>""),$A$24:$A34),$A$3,"Scenario",$B34,"Subsector",G$23),0))} -> 17.432888 | H34: {=IF(LOOKUP(2,1/($A$24:$A34<>""),$A$24:$A34)<2025,0,IFERROR(GETPIVOTDATA("Summe von "&LOOKUP(2,1/($A$24:$A34<>""),$A$24:$A34),$A$3,"Scenario",$B34,"Subsector",H$23),0))} -> 16.796 | I34: {=IF(LOOKUP(2,1/($A$24:$A34<>""),$A$24:$A34)<2025,0,IFERROR(GETPIVOTDATA("Summe von "&LOOKUP(2,1/($A$24:$A34<>""),$A$24:$A34),$A$3,"Scenario",$B34,"Subsector",I$23),0))} -> 3.701
B35: Orientierungsszenario_Strom | C35: {=IF(LOOKUP(2,1/($A$24:$A35<>""),$A$24:$A35)<2025,0,IFERROR(GETPIVOTDATA("Summe von "&LOOKUP(2,1/($A$24:$A35<>""),$A$24:$A35),$A$3,"Scenario",$B35,"Subsector",C$23),0))} -> 10.766591 | D35: {=IF(LOOKUP(2,1/($A$24:$A35<>""),$A$24:$A35)<2025,0,IFERROR(GETPIVOTDATA("Summe von "&LOOKUP(2,1/($A$24:$A35<>""),$A$24:$A35),$A$3,"Scenario",$B35,"Subsector",D$23),0))} -> 0 | E35: {=IF(LOOKUP(2,1/($A$24:$A35<>""),$A$24:$A35)<2025,0,IFERROR(GETPIVOTDATA("Summe von "&LOOKUP(2,1/($A$24:$A35<>""),$A$24:$A35),$A$3,"Scenario",$B35,"Subsector",E$23),0))} -> 0 | F35: {=IF(LOOKUP(2,1/($A$24:$A35<>""),$A$24:$A35)<2025,0,IFERROR(GETPIVOTDATA("Summe von "&LOOKUP(2,1/($A$24:$A35<>""),$A$24:$A35),$A$3,"Scenario",$B35,"Subsector",F$23),0))} -> 3 | G35: {=IF(LOOKUP(2,1/($A$24:$A35<>""),$A$24:$A35)<2025,0,IFERROR(GETPIVOTDATA("Summe von "&LOOKUP(2,1/($A$24:$A35<>""),$A$24:$A35),$A$3,"Scenario",$B35,"Subsector",G$23),0))} -> 17.432888 | H35: {=IF(LOOKUP(2,1/($A$24:$A35<>""),$A$24:$A35)<2025,0,IFERROR(GETPIVOTDATA("Summe von "&LOOKUP(2,1/($A$24:$A35<>""),$A$24:$A35),$A$3,"Scenario",$B35,"Subsector",H$23),0))} -> 0 | I35: {=IF(LOOKUP(2,1/($A$24:$A35<>""),$A$24:$A35)<2025,0,IFERROR(GETPIVOTDATA("Summe von "&LOOKUP(2,1/($A$24:$A35<>""),$A$24:$A35),$A$3,"Scenario",$B35,"Subsector",I$23),0))} -> 0
A36: 2050 | B36: Industrie-CCS | C36: {=IF(LOOKUP(2,1/($A$24:$A36<>""),$A$24:$A36)<2025,0,IFERROR(GETPIVOTDATA("Summe von "&LOOKUP(2,1/($A$24:$A36<>""),$A$24:$A36),$A$3,"Scenario",$B36,"Subsector",C$23),0))} -> 10.766591 | D36: {=IF(LOOKUP(2,1/($A$24:$A36<>""),$A$24:$A36)<2025,0,IFERROR(GETPIVOTDATA("Summe von "&LOOKUP(2,1/($A$24:$A36<>""),$A$24:$A36),$A$3,"Scenario",$B36,"Subsector",D$23),0))} -> 13.572 | E36: {=IF(LOOKUP(2,1/($A$24:$A36<>""),$A$24:$A36)<2025,0,IFERROR(GETPIVOTDATA("Summe von "&LOOKUP(2,1/($A$24:$A36<>""),$A$24:$A36),$A$3,"Scenario",$B36,"Subsector",E$23),0))} -> 25.2785 | F36: {=IF(LOOKUP(2,1/($A$24:$A36<>""),$A$24:$A36)<2025,0,IFERROR(GETPIVOTDATA("Summe von "&LOOKUP(2,1/($A$24:$A36<>""),$A$24:$A36),$A$3,"Scenario",$B36,"Subsector",F$23),0))} -> 3 | G36: {=IF(LOOKUP(2,1/($A$24:$A36<>""),$A$24:$A36)<2025,0,IFERROR(GETPIVOTDATA("Summe von "&LOOKUP(2,1/($A$24:$A36<>""),$A$24:$A36),$A$3,"Scenario",$B36,"Subsector",G$23),0))} -> 17.432888 | H36: {=IF(LOOKUP(2,1/($A$24:$A36<>""),$A$24:$A36)<2025,0,IFERROR(GETPIVOTDATA("Summe von "&LOOKUP(2,1/($A$24:$A36<>""),$A$24:$A36),$A$3,"Scenario",$B36,"Subsector",H$23),0))} -> 16.796 | I36: {=IF(LOOKUP(2,1/($A$24:$A36<>""),$A$24:$A36)<2025,0,IFERROR(GETPIVOTDATA("Summe von "&LOOKUP(2,1/($A$24:$A36<>""),$A$24:$A36),$A$3,"Scenario",$B36,"Subsector",I$23),0))} -> 3.701
B37: Orientierungsszenario_Strom | C37: {=IF(LOOKUP(2,1/($A$24:$A37<>""),$A$24:$A37)<2025,0,IFERROR(GETPIVOTDATA("Summe von "&LOOKUP(2,1/($A$24:$A37<>""),$A$24:$A37),$A$3,"Scenario",$B37,"Subsector",C$23),0))} -> 10.766591 | D37: {=IF(LOOKUP(2,1/($A$24:$A37<>""),$A$24:$A37)<2025,0,IFERROR(GETPIVOTDATA("Summe von "&LOOKUP(2,1/($A$24:$A37<>""),$A$24:$A37),$A$3,"Scenario",$B37,"Subsector",D$23),0))} -> 0 | E37: {=IF(LOOKUP(2,1/($A$24:$A37<>""),$A$24:$A37)<2025,0,IFERROR(GETPIVOTDATA("Summe von "&LOOKUP(2,1/($A$24:$A37<>""),$A$24:$A37),$A$3,"Scenario",$B37,"Subsector",E$23),0))} -> 0 | F37: {=IF(LOOKUP(2,1/($A$24:$A37<>""),$A$24:$A37)<2025,0,IFERROR(GETPIVOTDATA("Summe von "&LOOKUP(2,1/($A$24:$A37<>""),$A$24:$A37),$A$3,"Scenario",$B37,"Subsector",F$23),0))} -> 3 | G37: {=IF(LOOKUP(2,1/($A$24:$A37<>""),$A$24:$A37)<2025,0,IFERROR(GETPIVOTDATA("Summe von "&LOOKUP(2,1/($A$24:$A37<>""),$A$24:$A37),$A$3,"Scenario",$B37,"Subsector",G$23),0))} -> 17.432888 | H37: {=IF(LOOKUP(2,1/($A$24:$A37<>""),$A$24:$A37)<2025,0,IFERROR(GETPIVOTDATA("Summe von "&LOOKUP(2,1/($A$24:$A37<>""),$A$24:$A37),$A$3,"Scenario",$B37,"Subsector",H$23),0))} -> 0 | I37: {=IF(LOOKUP(2,1/($A$24:$A37<>""),$A$24:$A37)<2025,0,IFERROR(GETPIVOTDATA("Summe von "&LOOKUP(2,1/($A$24:$A37<>""),$A$24:$A37),$A$3,"Scenario",$B37,"Subsector",I$23),0))} -> 0

Sheet process_emissions_S1
A1: Scenario | B1: Country | C1: Energy_carrier | D1: Sector | E1: Region | F1: Name_Region | G1: Subsector | H1: Application | I1: Technologie | J1: latitude | K1: longitude | L1: Unit | M1: 2021 | N1: 2025 | O1: 2030 | P1: 2035 | Q1: 2040 | R1: 2045 | S1: 2050
A2: Orientierungsszenario_Strom | B2: DE | C2: process_emissions | D2: Industry | E2: DE11C | F2: Heidenheim | G2: Cement clinker | H2: CO2 capture | J2: 48.653687 | K2: 10.162468 | L2: CO2-Abscheidung [Mt/a] | M2: 0.41305296 | N2: 0.36142134 | O2: 0.39179288 | P2: 0.35838419 | Q2: 0.32801265 | R2: 0.29460395 | S2: 0.29460395
A3: Orientierungsszenario_Strom | B3: DE | C3: process_emissions | D3: Industry | E3: DE128 | F3: Rhein-Neckar-Kreis | G3: Cement clinker | H3: CO2 capture | J3: 49.357679 | K3: 8.6858324 | L3: CO2-Abscheidung [Mt/a] | M3: 0.38308692 | N3: 0.38308692 | O3: 0.33520105 | P3: 0.36336921 | Q3: 0.33238424 | R3: 0.30421608 | S3: 0.30421608
A4: Orientierungsszenario_Strom | B4: DE | C4: process_emissions | D4: Industry | E4: DE123 | F4: Karlsruhe, Landkreis | G4: Cement clinker | H4: CO2 capture | J4: 49.018413 | K4: 8.6124897 | L4: CO2-Abscheidung [Mt/a] | M4: 0.35976088 | N4: 0.35976088 | O4: 0.31479077 | P4: 0.34124378 | Q4: 0.31214547 | R4: 0.28569246 | S4: 0.28569246
A5: Orientierungsszenario_Strom | B5: DE | C5: process_emissions | D5: Industry | E5: DE145 | F5: Alb-Donau-Kreis | G5: Cement clinker | H5: CO2 capture | J5: 48.331986 | K5: 9.7304687 | L5: CO2-Abscheidung [Mt/a] | M5: 0.45278304 | N5: 0.45278304 | O5: 0.39618516 | P5: 0.42947803 | Q5: 0.39285587 | R5: 0.359563 | S5: 0.359563
A6: Orientierungsszenario_Strom | B6: DE | C6: process_emissions | D6: Industry | E6: DE145 | F6: Alb-Donau-Kreis | G6: Cement clinker | H6: CO2 capture | J6: 48.368603 | K6: 9.7346784 | L6: CO2-Abscheidung [Mt/a] | M6: 0.60784704 | N6: 0.60784704 | O6: 0.53186616 | P6: 0.57656079 | Q6: 0.52739669 | R6: 0.48270206 | S6: 0.48270206
A7: Orientierungsszenario_Strom | B7: DE | C7: process_emissions | D7: Industry | E7: DE143 | F7: Zollernalbkreis | G7: Cement clinker | H7: CO2 capture | J7: 48.227041 | K7: 8.7790961 | L7: CO2-Abscheidung [Mt/a] | M7: 0.5262956 | N7: 0.5262956 | O7: 0.46050865 | P7: 0.49920685 | Q7: 0.45663883 | R7: 0.41794062 | S7: 0.41794062
A8: Orientierungsszenario_Strom | B8: DE | C8: process_emissions | D8: Industry | E8: DEF0E | F8: Steinburg | G8: Cement clinker | H8: CO2 capture | J8: 53.874165 | K8: 9.5832686 | L8: CO2-Abscheidung [Mt/a] | M8: 0.79108328 | N8: 0.79108328 | O8: 0.69219787 | P8: 0.75036576 | Q8: 0.68638108 | R8: 0.6282132 | S8: 0.6282132
A9: Orientierungsszenario_Strom | B9: DE | C9: process_emissions | D9: Industry | E9: DE929 | F9: Region Hannover | G9: Cement clinker | H9: CO2 capture | J9: 52.349831 | K9: 9.8859339 | L9: CO2-Abscheidung [Mt/a] | M9: 0.46625868 | N9: 0.46625868 | O9: 0.40797635 | P9: 0.44226007 | Q9: 0.40454797 | R9: 0.37026425 | S9: 0.37026425
A10: Orientierungsszenario_Strom | B10: DE | C10: process_emissions | D10: Industry | E10: DEA38 | F10: Warendorf | G10: Cement clinker | H10: CO2 capture | J10: 51.765174 | K10: 8.0540288 | L10: CO2-Abscheidung [Mt/a] | M10: 0.41116984 | N10: 0.41116984 | O10: 0.35977361 | P10: 0.39000669 | Q10: 0.3567503 | R10: 0.32651723 | S10: 0.32651723
A11: Orientierungsszenario_Strom | B11: DE | C11: process_emissions | D11: Industry | E11: DEA37 | F11: Steinfurt | G11: Cement clinker | H11: CO2 capture | J11: 52.174986 | K11: 7.8878276 | L11: CO2-Abscheidung [Mt/a] | M11: 0.78009608 | N11: 0.78009608 | O11: 0.68258407 | P11: 0.73994407 | Q11: 0.67684807 | R11: 0.61948806 | S11: 0.61948806
A12: Orientierungsszenario_Strom | B12: DE | C12: process_emissions | D12: Industry | E12: DEA47 | F12: Paderborn | G12: Cement clinker | H12: CO2 capture | J12: 51.698988 | K12: 8.7470409 | L12: CO2-Abscheidung [Mt/a] | M12: 0.16345647 | N12: 0.16345647 | O12: 0.14302441 | P12: 0.15504327 | Q12: 0.14182253 | R12: 0.12980367 | S12: 0.12980367
A13: Orientierungsszenario_Strom | B13: DE | C13: process_emissions | D13: Industry | E13: DEA5B | F13: Soest | G13: Cement clinker | H13: CO2 capture | J13: 51.622561 | K13: 8.5043929 | L13: CO2-Abscheidung [Mt/a] | M13: 0.18801528 | N13: 0.18801528 | O13: 0.16451337 | P13: 0.17833803 | Q13: 0.16313091 | R13: 0.14930625 | S13: 0.14930625
... A176: Orientierungsszenario_Strom | B176: DE | C176: process_emissions | D176: Industry | E176: DE949 | F176: Emsland | G176: municipal waste incinerator. | H176: CO2 capture | J176: 52.313141 | K176: 7.3507255 | L176: CO2-Abscheidung [Mt/a] | M176: 0 | N176: 0.002771479 | O176: 0.016144496 | P176: 0.039555652 | Q176: 0.058596385 | R176: 0.081407439 | S176: 0.081407439

Sheet process_emissions_S2
A1: Scenario | B1: Country | C1: Energy_carrier | D1: Sector | E1: Region | F1: Name_Region | G1: Subsector | H1: Application | I1: Technologie | J1: latitude | K1: longitude | L1: Unit | M1: 2021 | N1: 2025 | O1: 2030 | P1: 2035 | Q1: 2040 | R1: 2045 | S1: 2050
A2: Industrie-CCS | B2: DE | C2: process_emissions | D2: Industry | E2: DE11C | F2: Heidenheim | G2: Cement clinker | H2: CO2 capture | J2: 48.653687 | K2: 10.162468 | L2: CO2-Abscheidung [Mt/a] | M2: 0.41305296 | N2: 0.36142134 | O2: 0.39179288 | P2: 0.35838419 | Q2: 0.32801265 | R2: 0.29460395 | S2: 0.29460395
A3: Industrie-CCS | B3: DE | C3: process_emissions | D3: Industry | E3: DE128 | F3: Rhein-Neckar-Kreis | G3: Cement clinker | H3: CO2 capture | J3: 49.357679 | K3: 8.6858324 | L3: CO2-Abscheidung [Mt/a] | M3: 0.38308692 | N3: 0.38308692 | O3: 0.33520105 | P3: 0.36336921 | Q3: 0.33238424 | R3: 0.30421608 | S3: 0.30421608
A4: Industrie-CCS | B4: DE | C4: process_emissions | D4: Industry | E4: DE123 | F4: Karlsruhe, Landkreis | G4: Cement clinker | H4: CO2 capture | J4: 49.018413 | K4: 8.6124897 | L4: CO2-Abscheidung [Mt/a] | M4: 0.35976088 | N4: 0.35976088 | O4: 0.31479077 | P4: 0.34124378 | Q4: 0.31214547 | R4: 0.28569246 | S4: 0.28569246
A5: Industrie-CCS | B5: DE | C5: process_emissions | D5: Industry | E5: DE145 | F5: Alb-Donau-Kreis | G5: Cement clinker | H5: CO2 capture | J5: 48.331986 | K5: 9.7304687 | L5: CO2-Abscheidung [Mt/a] | M5: 0.45278304 | N5: 0.45278304 | O5: 0.39618516 | P5: 0.42947803 | Q5: 0.39285587 | R5: 0.359563 | S5: 0.359563
A6: Industrie-CCS | B6: DE | C6: process_emissions | D6: Industry | E6: DE145 | F6: Alb-Donau-Kreis | G6: Cement clinker | H6: CO2 capture | J6: 48.368603 | K6: 9.7346784 | L6: CO2-Abscheidung [Mt/a] | M6: 0.60784704 | N6: 0.60784704 | O6: 0.53186616 | P6: 0.57656079 | Q6: 0.52739669 | R6: 0.48270206 | S6: 0.48270206
A7: Industrie-CCS | B7: DE | C7: process_emissions | D7: Industry | E7: DE143 | F7: Zollernalbkreis | G7: Cement clinker | H7: CO2 capture | J7: 48.227041 | K7: 8.7790961 | L7: CO2-Abscheidung [Mt/a] | M7: 0.5262956 | N7: 0.5262956 | O7: 0.46050865 | P7: 0.49920685 | Q7: 0.45663883 | R7: 0.41794062 | S7: 0.41794062
A8: Industrie-CCS | B8: DE | C8: process_emissions | D8: Industry | E8: DEF0E | F8: Steinburg | G8: Cement clinker | H8: CO2 capture | J8: 53.874165 | K8: 9.5832686 | L8: CO2-Abscheidung [Mt/a] | M8: 0.79108328 | N8: 0.79108328 | O8: 0.69219787 | P8: 0.75036576 | Q8: 0.68638108 | R8: 0.6282132 | S8: 0.6282132
A9: Industrie-CCS | B9: DE | C9: process_emissions | D9: Industry | E9: DE929 | F9: Region Hannover | G9: Cement clinker | H9: CO2 capture | J9: 52.349831 | K9: 9.8859339 | L9: CO2-Abscheidung [Mt/a] | M9: 0.46625868 | N9: 0.46625868 | O9: 0.40797635 | P9: 0.44226007 | Q9: 0.40454797 | R9: 0.37026425 | S9: 0.37026425
A10: Industrie-CCS | B10: DE | C10: process_emissions | D10: Industry | E10: DEA38 | F10: Warendorf | G10: Cement clinker | H10: CO2 capture | J10: 51.765174 | K10: 8.0540288 | L10: CO2-Abscheidung [Mt/a] | M10: 0.41116984 | N10: 0.41116984 | O10: 0.35977361 | P10: 0.39000669 | Q10: 0.3567503 | R10: 0.32651723 | S10: 0.32651723
A11: Industrie-CCS | B11: DE | C11: process_emissions | D11: Industry | E11: DEA37 | F11: Steinfurt | G11: Cement clinker | H11: CO2 capture | J11: 52.174986 | K11: 7.8878276 | L11: CO2-Abscheidung [Mt/a] | M11: 0.78009608 | N11: 0.78009608 | O11: 0.68258407 | P11: 0.73994407 | Q11: 0.67684807 | R11: 0.61948806 | S11: 0.61948806
A12: Industrie-CCS | B12: DE | C12: process_emissions | D12: Industry | E12: DEA47 | F12: Paderborn | G12: Cement clinker | H12: CO2 capture | J12: 51.698988 | K12: 8.7470409 | L12: CO2-Abscheidung [Mt/a] | M12: 0.16345647 | N12: 0.16345647 | O12: 0.14302441 | P12: 0.15504327 | Q12: 0.14182253 | R12: 0.12980367 | S12: 0.12980367
A13: Industrie-CCS | B13: DE | C13: process_emissions | D13: Industry | E13: DEA5B | F13: Soest | G13: Cement clinker | H13: CO2 capture | J13: 51.622561 | K13: 8.5043929 | L13: CO2-Abscheidung [Mt/a] | M13: 0.18801528 | N13: 0.18801528 | O13: 0.16451337 | P13: 0.17833803 | Q13: 0.16313091 | R13: 0.14930625 | S13: 0.14930625
... A212: Industrie-CCS | B212: DE | C212: process_emissions | D212: Industry | E212: DEF05 | F212: Dithmarschen | G212: Refinery | H212: CO2 capture | J212: 53.983279 | K212: 9.098461 | L212: CO2-Abscheidung [Mt/a] | M212: 0 | N212: 0 | O212: 0 | P212: 0.628667 | Q212: 1.257333 | R212: 1.886 | S212: 1.886

Sheet process_emissions
A1: Scenario | B1: Country | C1: Energy_carrier | D1: Sector | E1: Region | F1: Name_Region | G1: Subsector | H1: Application | I1: Technologie | J1: latitude | K1: longitude | L1: Unit | M1: 2021 | N1: 2025 | O1: 2030 | P1: 2035 | Q1: 2040 | R1: 2045 | S1: 2050
A2: Orientierungsszenario_Strom | B2: DE | C2: process_emissions | D2: Industry | E2: DE11C | F2: Heidenheim | G2: Cement clinker | H2: CO2 capture | J2: 48.653687 | K2: 10.162468 | L2: CO2-Abscheidung [Mt/a] | M2: 0.41305296 | N2: 0.36142134 | O2: 0.39179288 | P2: 0.35838419 | Q2: 0.32801265 | R2: 0.29460395 | S2: 0.29460395
A3: Orientierungsszenario_Strom | B3: DE | C3: process_emissions | D3: Industry | E3: DE128 | F3: Rhein-Neckar-Kreis | G3: Cement clinker | H3: CO2 capture | J3: 49.357679 | K3: 8.6858324 | L3: CO2-Abscheidung [Mt/a] | M3: 0.38308692 | N3: 0.38308692 | O3: 0.33520105 | P3: 0.36336921 | Q3: 0.33238424 | R3: 0.30421608 | S3: 0.30421608
A4: Orientierungsszenario_Strom | B4: DE | C4: process_emissions | D4: Industry | E4: DE123 | F4: Karlsruhe, Landkreis | G4: Cement clinker | H4: CO2 capture | J4: 49.018413 | K4: 8.6124897 | L4: CO2-Abscheidung [Mt/a] | M4: 0.35976088 | N4: 0.35976088 | O4: 0.31479077 | P4: 0.34124377 | Q4: 0.31214547 | R4: 0.28569246 | S4: 0.28569246
A5: Orientierungsszenario_Strom | B5: DE | C5: process_emissions | D5: Industry | E5: DE145 | F5: Alb-Donau-Kreis | G5: Cement clinker | H5: CO2 capture | J5: 48.331986 | K5: 9.7304687 | L5: CO2-Abscheidung [Mt/a] | M5: 0.45278304 | N5: 0.45278304 | O5: 0.39618516 | P5: 0.42947803 | Q5: 0.39285587 | R5: 0.359563 | S5: 0.359563
A6: Orientierungsszenario_Strom | B6: DE | C6: process_emissions | D6: Industry | E6: DE145 | F6: Alb-Donau-Kreis | G6: Cement clinker | H6: CO2 capture | J6: 48.368603 | K6: 9.7346784 | L6: CO2-Abscheidung [Mt/a] | M6: 0.60784704 | N6: 0.60784704 | O6: 0.53186616 | P6: 0.57656079 | Q6: 0.52739669 | R6: 0.48270206 | S6: 0.48270206
A7: Orientierungsszenario_Strom | B7: DE | C7: process_emissions | D7: Industry | E7: DE143 | F7: Zollernalbkreis | G7: Cement clinker | H7: CO2 capture | J7: 48.227041 | K7: 8.7790961 | L7: CO2-Abscheidung [Mt/a] | M7: 0.5262956 | N7: 0.5262956 | O7: 0.46050865 | P7: 0.49920685 | Q7: 0.45663883 | R7: 0.41794062 | S7: 0.41794062
A8: Orientierungsszenario_Strom | B8: DE | C8: process_emissions | D8: Industry | E8: DEF0E | F8: Steinburg | G8: Cement clinker | H8: CO2 capture | J8: 53.874165 | K8: 9.5832686 | L8: CO2-Abscheidung [Mt/a] | M8: 0.79108328 | N8: 0.79108328 | O8: 0.69219787 | P8: 0.75036576 | Q8: 0.68638108 | R8: 0.6282132 | S8: 0.6282132
A9: Orientierungsszenario_Strom | B9: DE | C9: process_emissions | D9: Industry | E9: DE929 | F9: Region Hannover | G9: Cement clinker | H9: CO2 capture | J9: 52.349831 | K9: 9.8859339 | L9: CO2-Abscheidung [Mt/a] | M9: 0.46625868 | N9: 0.46625868 | O9: 0.40797634 | P9: 0.44226007 | Q9: 0.40454797 | R9: 0.37026425 | S9: 0.37026425
A10: Orientierungsszenario_Strom | B10: DE | C10: process_emissions | D10: Industry | E10: DEA38 | F10: Warendorf | G10: Cement clinker | H10: CO2 capture | J10: 51.765174 | K10: 8.0540288 | L10: CO2-Abscheidung [Mt/a] | M10: 0.41116984 | N10: 0.41116984 | O10: 0.35977361 | P10: 0.39000669 | Q10: 0.3567503 | R10: 0.32651723 | S10: 0.32651723
A11: Orientierungsszenario_Strom | B11: DE | C11: process_emissions | D11: Industry | E11: DEA37 | F11: Steinfurt | G11: Cement clinker | H11: CO2 capture | J11: 52.174986 | K11: 7.8878276 | L11: CO2-Abscheidung [Mt/a] | M11: 0.78009608 | N11: 0.78009608 | O11: 0.68258407 | P11: 0.73994407 | Q11: 0.67684807 | R11: 0.61948806 | S11: 0.61948806
A12: Orientierungsszenario_Strom | B12: DE | C12: process_emissions | D12: Industry | E12: DEA47 | F12: Paderborn | G12: Cement clinker | H12: CO2 capture | J12: 51.698988 | K12: 8.7470409 | L12: CO2-Abscheidung [Mt/a] | M12: 0.16345647 | N12: 0.16345647 | O12: 0.14302441 | P12: 0.15504327 | Q12: 0.14182253 | R12: 0.12980367 | S12: 0.12980367
A13: Orientierungsszenario_Strom | B13: DE | C13: process_emissions | D13: Industry | E13: DEA5B | F13: Soest | G13: Cement clinker | H13: CO2 capture | J13: 51.622561 | K13: 8.5043929 | L13: CO2-Abscheidung [Mt/a] | M13: 0.18801528 | N13: 0.18801528 | O13: 0.16451337 | P13: 0.17833803 | Q13: 0.16313091 | R13: 0.14930625 | S13: 0.14930625
... A100: Orientierungsszenario_Strom | B100: DE | C100: process_emissions | D100: Industry | E100: DEB37 | F100: Pirmasens, Kreisfreie Stadt | G100: municipal waste incinerator. | H100: CO2 capture | J100: 49.228362 | K100: 7.5947836 | L100: CO2-Abscheidung [Mt/a] | M100: 0 | N100: 0.0038374324 | O100: 0.022353918 | P100: 0.054769364 | Q100: 0.081133456 | R100: 0.11271799 | S100: 0.11271799
A101: Orientierungsszenario_Strom | B101: DE | C101: process_emissions | D101: Industry | E101: 37956 | F101: Neunkirchen | G101: municipal waste incinerator. | H101: CO2 capture | J101: 49.338382 | K101: 7.1695241 | L101: CO2-Abscheidung [Mt/a] | M101: 0 | N101: 0.0038374324 | O101: 0.022353918 | P101: 0.054769364 | Q101: 0.081133456 | R101: 0.11271799 | S101: 0.11271799
A102: Orientierungsszenario_Strom | B102: DE | C102: process_emissions | D102: Industry | E102: 37226 | F102: Regionalverband Saarbrücken | G102: municipal waste incinerator. | H102: CO2 capture | J102: 49.214184 | K102: 6.8342257 | L102: CO2-Abscheidung [Mt/a] | M102: 0 | N102: 0.0054363626 | O102: 0.031668051 | P102: 0.077589933 | Q102: 0.11493906 | R102: 0.15968382 | S102: 0.15968382
A103: Orientierungsszenario_Strom | B103: DE | C103: process_emissions | D103: Industry | E103: DE126 | F103: Mannheim, Stadtkreis | G103: municipal waste incinerator. | H103: CO2 capture | J103: 49.524153 | K103: 8.4520348 | L103: CO2-Abscheidung [Mt/a] | M103: 0 | N103: 0.014923348 | O103: 0.086931904 | P103: 0.21299197 | Q103: 0.315519 | R103: 0.43834775 | S103: 0.43834775
A104: Orientierungsszenario_Strom | B104: DE | C104: process_emissions | D104: Industry | E104: DE241 | F104: Bamberg, Kreisfreie Stadt | G104: municipal waste incinerator. | H104: CO2 capture | J104: 49.911261 | K104: 10.854452 | L104: CO2-Abscheidung [Mt/a] | M104: 0 | N104: 0.0025445162 | O104: 0.014822386 | P104: 0.036316348 | Q104: 0.053797792 | R104: 0.074740796 | S104: 0.074740796
A105: Orientierungsszenario_Strom | B105: DE | C105: process_emissions | D105: Industry | E105: DE243 | F105: Coburg, Kreisfreie Stadt | G105: municipal waste incinerator. | H105: CO2 capture | J105: 50.284546 | K105: 10.954892 | L105: CO2-Abscheidung [Mt/a] | M105: 0 | N105: 0.0030273078 | O105: 0.017634758 | P105: 0.043206943 | Q105: 0.064005282 | R105: 0.088921971 | S105: 0.088921971
A106: Orientierungsszenario_Strom | B106: DE | C106: process_emissions | D106: Industry | E106: DE262 | F106: Schweinfurt, Kreisfreie Stadt | G106: municipal waste incinerator. | H106: CO2 capture | J106: 50.030027 | K106: 10.223978 | L106: CO2-Abscheidung [Mt/a] | M106: 0 | N106: 0.0041742737 | O106: 0.024316095 | P106: 0.059576897 | Q106: 0.08825517 | R106: 0.12261213 | S106: 0.12261213
A107: Orientierungsszenario_Strom | B107: DE | C107: process_emissions | D107: Industry | E107: DE263 | F107: Würzburg, Kreisfreie Stadt | G107: municipal waste incinerator. | H107: CO2 capture | J107: 49.79306 | K107: 9.9938928 | L107: CO2-Abscheidung [Mt/a] | M107: 0 | N107: 0.0042638138 | O107: 0.024837687 | P107: 0.060854849 | Q107: 0.090148284 | R107: 0.12524221 | S107: 0.12524221
A108: Orientierungsszenario_Strom | B108: DE | C108: process_emissions | D108: Industry | E108: DE71C | F108: Offenbach, Landkreis | G108: municipal waste incinerator. | H108: CO2 capture | J108: 50.065175 | K108: 8.7686208 | L108: CO2-Abscheidung [Mt/a] | M108: 0 | N108: 0.0063957207 | O108: 0.03725653 | P108: 0.091282274 | Q108: 0.13522243 | R108: 0.18786332 | S108: 0.18786332
A109: Orientierungsszenario_Strom | B109: DE | C109: process_emissions | D109: Industry | E109: DE712 | F109: Frankfurt am Main, Kreisfreie Stadt | G109: municipal waste incinerator. | H109: CO2 capture | J109: 50.161786 | K109: 8.6353335 | L109: CO2-Abscheidung [Mt/a] | M109: 0 | N109: 0.014390372 | O109: 0.083827193 | P109: 0.20538512 | Q109: 0.30425046 | R109: 0.42269247 | S109: 0.42269247
A110: Orientierungsszenario_Strom | B110: DE | C110: process_emissions | D110: Industry | E110: DE714 | F110: Wiesbaden, Kreisfreie Stadt | G110: municipal waste incinerator. | H110: CO2 capture | J110: 50.025569 | K110: 8.2429431 | L110: CO2-Abscheidung [Mt/a] | M110: 0 | N110: 0.0072484835 | O110: 0.042224067 | P110: 0.10345324 | Q110: 0.15325208 | R110: 0.21291176 | S110: 0.21291176
A111: Orientierungsszenario_Strom | B111: DE | C111: process_emissions | D111: Industry | E111: DE714 | F111: Wiesbaden, Kreisfreie Stadt | G111: municipal waste incinerator. | H111: CO2 capture | J111: 50.042578 | K111: 8.2625524 | L111: CO2-Abscheidung [Mt/a] | M111: 0 | N111: 0.0041572185 | O111: 0.024216745 | P111: 0.059333478 | Q111: 0.087894577 | R111: 0.12211116 | S111: 0.12211116
A112: Orientierungsszenario_Strom | B112: DE | C112: process_emissions | D112: Industry | E112: DE712 | F112: Frankfurt am Main, Kreisfreie Stadt | G112: municipal waste incinerator. | H112: CO2 capture | J112: 50.079951 | K112: 8.5324264 | L112: CO2-Abscheidung [Mt/a] | M112: 0 | N112: 0.014923348 | O112: 0.086931904 | P112: 0.21299197 | Q112: 0.315519 | R112: 0.43834775 | S112: 0.43834775
A113: Orientierungsszenario_Strom | B113: DE | C113: process_emissions | D113: Industry | E113: DE711 | F113: Darmstadt, Kreisfreie Stadt | G113: municipal waste incinerator. | H113: CO2 capture | J113: 49.88355 | K113: 8.6452618 | L113: CO2-Abscheidung [Mt/a] | M113: 0 | N113: 0.00045196427 | O113: 0.0026327948 | P113: 0.006450614 | Q113: 0.0095557181 | R113: 0.013275675 | S113: 0.013275675
A114: Orientierungsszenario_Strom | B114: DE | C114: process_emissions | D114: Industry | E114: DEG0I | F114: Saalfeld-Rudolstadt | G114: municipal waste incinerator. | H114: CO2 capture | J114: 50.686881 | K114: 11.330251 | L114: CO2-Abscheidung [Mt/a] | M114: 0 | N114: 0.0017055255 | O114: 0.0099350747 | P114: 0.02434194 | Q114: 0.036059314 | R114: 0.050096885 | S114: 0.050096885
... A212: Orientierungsszenario_Strom | B212: DE | C212: process_emissions | D212: Industry | E212: DEF05 | F212: Dithmarschen | G212: Refinery | H212: CO2 capture | J212: 53.983279 | K212: 9.098461 | L212: CO2-Abscheidung [Mt/a] | M212: 0 | N212: 0 | O212: 0 | P212: 0.628667 | Q212: 1.257333 | R212: 1.886 | S212: 1.886

Sheet Zement_O_Strom
A1: Lat | B1: Lon | C1: CO2-Abscheidung [t/a] | D1: % | E1: 2021 | F1: 2025 | G1: 2030 | H1: 2035 | I1: 2040 | J1: 2045 | K1: 2050
A2: 48.653687 | B2: 10.162468 | C2: 272877.7 | D2: =C2/$C$32 -> 0.030371541 | E2: =$D2*'Process-emission_LFS'!C$2 -> 0.41305296 | F2: =$D2*'Process-emission_LFS'!D$2 -> 0.36142134 | G2: =$D2*'Process-emission_LFS'!E$2 -> 0.39179288 | H2: =$D2*'Process-emission_LFS'!F$2 -> 0.35838419 | I2: =$D2*'Process-emission_LFS'!G$2 -> 0.32801265 | J2: =$D2*'Process-emission_LFS'!H$2 -> 0.29460395
A3: 49.357679 | B3: 8.6858324 | C3: 253081.05 | D3: =C3/$C$32 -> 0.028168156 | E3: =$D3*'Process-emission_LFS'!C$2 -> 0.38308692 | F3: =$D3*'Process-emission_LFS'!C$2 -> 0.38308692 | G3: =$D3*'Process-emission_LFS'!D$2 -> 0.33520105 | H3: =$D3*'Process-emission_LFS'!E$2 -> 0.36336921 | I3: =$D3*'Process-emission_LFS'!F$2 -> 0.33238424 | J3: =$D3*'Process-emission_LFS'!G$2 -> 0.30421608
A4: 49.018413 | B4: 8.6124897 | C4: 237671.02 | D4: =C4/$C$32 -> 0.026453006 | E4: =$D4*'Process-emission_LFS'!C$2 -> 0.35976088 | F4: =$D4*'Process-emission_LFS'!C$2 -> 0.35976088 | G4: =$D4*'Process-emission_LFS'!D$2 -> 0.31479077 | H4: =$D4*'Process-emission_LFS'!E$2 -> 0.34124377 | I4: =$D4*'Process-emission_LFS'!F$2 -> 0.31214547 | J4: =$D4*'Process-emission_LFS'!G$2 -> 0.28569246
A5: 48.331986 | B5: 9.7304687 | C5: 299124.82 | D5: =C5/$C$32 -> 0.03329287 | E5: =$D5*'Process-emission_LFS'!C$2 -> 0.45278304 | F5: =$D5*'Process-emission_LFS'!C$2 -> 0.45278304 | G5: =$D5*'Process-emission_LFS'!D$2 -> 0.39618516 | H5: =$D5*'Process-emission_LFS'!E$2 -> 0.42947803 | I5: =$D5*'Process-emission_LFS'!F$2 -> 0.39285587 | J5: =$D5*'Process-emission_LFS'!G$2 -> 0.359563
A6: 48.368603 | B6: 9.7346784 | C6: 401565.7 | D6: =C6/$C$32 -> 0.044694635 | E6: =$D6*'Process-emission_LFS'!C$2 -> 0.60784704 | F6: =$D6*'Process-emission_LFS'!C$2 -> 0.60784704 | G6: =$D6*'Process-emission_LFS'!D$2 -> 0.53186616 | H6: =$D6*'Process-emission_LFS'!E$2 -> 0.57656079 | I6: =$D6*'Process-emission_LFS'!F$2 -> 0.52739669 | J6: =$D6*'Process-emission_LFS'!G$2 -> 0.48270206
A7: 48.227041 | B7: 8.7790961 | C7: 347689.87 | D7: =C7/$C$32 -> 0.038698206 | E7: =$D7*'Process-emission_LFS'!C$2 -> 0.5262956 | F7: =$D7*'Process-emission_LFS'!C$2 -> 0.5262956 | G7: =$D7*'Process-emission_LFS'!D$2 -> 0.46050865 | H7: =$D7*'Process-emission_LFS'!E$2 -> 0.49920685 | I7: =$D7*'Process-emission_LFS'!F$2 -> 0.45663883 | J7: =$D7*'Process-emission_LFS'!G$2 -> 0.41794062
A8: 53.874165 | B8: 9.5832686 | C8: 522618.18 | D8: =C8/$C$32 -> 0.058167889 | E8: =$D8*'Process-emission_LFS'!C$2 -> 0.79108328 | F8: =$D8*'Process-emission_LFS'!C$2 -> 0.79108328 | G8: =$D8*'Process-emission_LFS'!D$2 -> 0.69219787 | H8: =$D8*'Process-emission_LFS'!E$2 -> 0.75036576 | I8: =$D8*'Process-emission_LFS'!F$2 -> 0.68638108 | J8: =$D8*'Process-emission_LFS'!G$2 -> 0.6282132
A9: 52.349831 | B9: 9.8859339 | C9: 308027.32 | D9: =C9/$C$32 -> 0.034283726 | E9: =$D9*'Process-emission_LFS'!C$2 -> 0.46625868 | F9: =$D9*'Process-emission_LFS'!C$2 -> 0.46625868 | G9: =$D9*'Process-emission_LFS'!D$2 -> 0.40797634 | H9: =$D9*'Process-emission_LFS'!E$2 -> 0.44226007 | I9: =$D9*'Process-emission_LFS'!F$2 -> 0.40454797 | J9: =$D9*'Process-emission_LFS'!G$2 -> 0.37026425
A10: 51.765174 | B10: 8.0540288 | C10: 271633.64 | D10: =C10/$C$32 -> 0.030233077 | E10: =$D10*'Process-emission_LFS'!C$2 -> 0.41116984 | F10: =$D10*'Process-emission_LFS'!C$2 -> 0.41116984 | G10: =$D10*'Process-emission_LFS'!D$2 -> 0.35977361 | H10: =$D10*'Process-emission_LFS'!E$2 -> 0.39000669 | I10: =$D10*'Process-emission_LFS'!F$2 -> 0.3567503 | J10: =$D10*'Process-emission_LFS'!G$2 -> 0.32651723
